<?xml version="1.0"?>
<robot name="delta_robot">

    <!-- RAILS -->
    <link name="rails_link">
        <collision>
            <origin xyz="0 0 9" rpy="0 0 0"/>
            <geometry>
                <mesh filename="/home/ostifede02/Documents/2dr_ws/src/deltarobot_description/meshes/rails_collision.stl" scale="0.9 1.5 0.9"/>
            </geometry>
        </collision>
    </link>
    <!-- RAILS END-->

    <!-- CARRIAGE 2 -->
    <link name="carriage_2_link">
    </link>

    <joint name="carriage_2_joint" type="prismatic">
        <origin xyz="0. 0. 0." rpy="0 0 0"/>
        <parent link="rails_link"/>
        <child link="carriage_2_link"/>
        <axis xyz="1 0 1"/>
        <limit lower="60" upper="350" velocity="0" effort="0"/> 
    </joint>
    <!-- CARRIAGE 2 END-->

    <!-- ROD 2 -->
    <link name="rod_2_link">
        <collision>
            <origin xyz="0 0 0" rpy="0 0 0"/>
            <geometry>
                <mesh filename="/home/ostifede02/Documents/2dr_ws/src/deltarobot_description/meshes/link_2.stl"/>
            </geometry>
        </collision>
    </link>

    <joint name="rod_2_joint" type="revolute">
        <origin xyz="0 0 0" rpy="0 0 0"/>
        <parent link="carriage_2_link"/>
        <child link="rod_2_link"/>
        <axis xyz="0 1 0"/>
        <limit lower="0" upper="6.28" velocity="0" effort="0"/> 
    </joint>

    <joint name="rod_2_end_effector_joint" type="fixed">
        <origin xyz="0 0 -450"/>
        <parent link="rod_2_link"/>
        <child link="rod_2_end_effector_link"/>
    </joint>
    <!-- ROD 2 END-->

    <!-- END EFFECTOR -->
    <link name="rod_2_end_effector_link">
    </link>
    <!-- END EFFECTOR END -->

</robot>